Workbook
Name PRICE: '1. Setup & Recap'!$I$47
Name CAW: '1. Setup & Recap'!$G$4

Sheet 1. Setup & Recap
A1: Scenario cost data | G1: $ or % | H1: Remarks | N1: Instructions:
N2: 1. Fill in yellow cells with your company information and project information below.
B3: Crew size (# people) | G3: 6 | N3: 2. Do not write over red cells as they contain formulas.
B4: Crew average wage (CAW) | G4: 23 | N4: 3. Change the descriptions as necessary.
B5: Man-hours per man per day | G5: 10 | N5: 4. Be sure to save and back up your worksheet.
B6: Overtime factor (OTF) | G6: 0.1 | H6: 40 hours per week | N6: 5. Go to sheet 2-A on the tab at the bottom of this page to input your production information.
B7: Risk factor (RF) | G7: 0.12 | N7: 6. Go to sheet 3 on the tab at the bottom of this page to input your general conditions information.
B8: Crew average wage w/OTF & RF | G8: =CAW+(G4*G6)+(G4*G7) -> 28.06
B9: Labor burden | G9: 0.285 | N9: Date:
B10: Sales tax | G10: 0.0825 | N10: Project:
B11: G&A overhead per hour (OPH) | G11: 21.45 | N11: Location:
B12: Net profit margin | G12: 0.25 | N12: P.O.C./G.C.:
B13: Crew truck with trailer | G13: 12 | N13: Phone / Fax:
B14: Curb time man-hours | G14: ='Landscape Intallation'!J6+'Lawn Installation'!J6+'2-C. Production costs'!J6 -> 515 | N14: Due Date:
B15: Total Days to complete Job | G15: =roundup(G14/(G5*G3-1),0) -> 9
B16: Number of units | G16: 1 | H16: LS | N16: Estimator: | O16: Hayden Lutz, Rob McKenna, John Dickinson
A18: Scenario | C18: Materials | E18: Labor | G18: Equipment | I18: Subcontractors | K18: Subtotals
A19: I. Production or "Curb" time costs
C20: ='Landscape Intallation'!I10+'Lawn Installation'!I10+'2-C. Production costs'!I10 -> 28583.59 | E20: ='Landscape Intallation'!J10+'Lawn Installation'!J10+'2-C. Production costs'!K10 -> 11845 | G20: ='Landscape Intallation'!K10+'Lawn Installation'!K10+'2-C. Production costs'!K10 -> 2362.9 | I20: ='Landscape Intallation'!L10+'Lawn Installation'!L10+'2-C. Production costs'!L10 -> 59986
C21: =SUM(C20) -> 28583.59 | E21: =SUM(E20) -> 11845 | G21: =SUM(G20) -> 2362.9 | I21: =SUM(I20) -> 59986 | K21: =C21+E21+G21+I21 -> 102777.49
A23: II. General conditions (off-site or non-curb-time costs)
C25: ='3. GC costs'!I10 -> 40 | E25: ='3. GC costs'!J10 -> 3225 | G25: ='3. GC costs'!K10 -> 1140 | I25: ='3. GC costs'!L10 -> 0
C26: =C25 -> 40 | E26: =E25 -> 3225 | G26: =G25 -> 1140 | I26: =I25 -> 0 | K26: =C26+E26+G26+I26 -> 4405
B28: Subtotals | C28: =C21+C26 -> 28623.59 | E28: =E21+E26 -> 15070 | G28: =G21+G26 -> 3502.9 | I28: =I21+I26 -> 59986 | K28: =C28+E28+G28+I28 -> 107182.49
A30: III. Margins & markups
B32: A.Sales tax | C32: =G10*C28 -> 2361.4462
B34: B.Labor burden | E34: =E28*$G$9 -> 4294.95
B36: Subtotals | C36: =C28+C32 -> 30985.036 | E36: =E34+E28 -> 19364.95 | G36: =G28 -> 3502.9 | I36: =I28 -> 59986
B38: Total direct costs (TDC) | I38: =SUM(C36:I36) -> 113838.89 | J38: TDC
B40: C. G&A overhead costs
B41: ='Landscape Intallation'!J6+'3. GC costs'!J6 -> 625.1 | C41: (Number of man-hours x OPH) | G41: =G11 -> 21.45 | H41: = | I41: =B41*G41 -> 13408.395
B42: BEP (TDC + G&A overhead) | I42: =I38+I41 -> 127247.28 | J42: BEP
B44: D. Contingency factor (if desired)
B45: E. Net profit margin
B46: =G12 -> 0.25 | I46: =I42/(1-B46)-I42 -> 42415.76
B47: F. Total price | I47: =I42+I44+I46 -> 169663.04
A48: -
A49: IV. Scenario analysis
B51: A. Unit price (Total price ÷ units)
C53: =PRICE -> 169663.04 | D53: divided by | F53: =G16 -> 1 | G53: = | I53: =C53/F53 -> 169663.04 | J53: Curb-time rate
...

Sheet Landscape Intallation
B1: Project: | C1: ='1. Setup & Recap'!O10 | F1: Date: | G1: ='1. Setup & Recap'!O9
B2: Location: | C2: ='1. Setup & Recap'!O11 | F2: Estimator: | G2: ='1. Setup & Recap'!O16 -> Hayden Lutz, Rob McKenna, John Dickinson | I2: CAW Loaded | J2: =$G$5*(1+$G$6+$G$7) -> 28.06
B3: P.O.C./G.C.: | C3: ='1. Setup & Recap'!O12 | F3: Crew Size: | G3: ='1. Setup & Recap'!G3 -> 6
B4: Phone / Fax: | C4: ='1. Setup & Recap'!O13 | F4: Hours/Day: | G4: ='1. Setup & Recap'!G5 -> 10
B5: Due Date: | C5: ='1. Setup & Recap'!O14 | F5: CAW: | G5: =CAW -> 23 | I5: Phase 1 | J5: Quantity | K5: Unit
B6: Type Work: | F6: Risk Factor | G6: ='1. Setup & Recap'!G7 -> 0.12 | I6: Total Labor Hrs | J6: =DSUM(F9:G998,F9,K5:K6) -> 498.1 | K6: Hrs L
F7: OT Factor | G7: ='1. Setup & Recap'!G6 -> 0.1
F8: Column Calcualtions | I8: =F8*H8 -> #VALUE! | J8: =F8*H8 -> #VALUE! | K8: =F8*H8 -> #VALUE! | L8: =F8*H8 -> #VALUE!
A9: # | B9: Description | F9: Quantity | G9: Unit | H9: Unit Cost | I9: Material | J9: Labor | K9: Equip | L9: Subs
B10: TOTALS | I10: =SUM(I11:I998) -> 26873.59 | J10: =SUM(J11:J998) -> 11456.3 | K10: =SUM(K11:K998) -> 2338 | L10: =SUM(L11:L998) -> 59986
B11: Materials
B12: Flagstone Stepping Stones | F12: 10 | G12: Each | H12: 23 | I12: =F12*H12 -> 230
B13: Tumbled Paving Stones (Patio) | F13: 788 | G13: Sq. Ft. | H13: 4.75 | I13: =F13*H13 -> 3743
B14: Paving Stone Border | F14: 385 | G14: Lin. Ft. | H14: 5 | I14: =F14*H14 -> 1925
B15: Flagstone Porch (Overlay) | F15: 51 | G15: Sq. Ft. | H15: 5.25 | I15: =F15*H15 -> 267.75
B16: Exposed Aggregate Concrete Mix | F16: 10 | G16: Cu. Yd. | H16: 165 | I16: =F16*H16 -> 1650
B17: Armour Stone Outcropping | F17: 8 | G17: Tons | H17: 215 | I17: =F17*H17 -> 1720
B18: Armour Stone Boulders (Deco) | F18: 5 | G18: Each | H18: 118 | I18: =F18*H18 -> 590
B19: Natural Stone Garden Wall | F19: 1.5 | G19: Tons | H19: 300 | I19: =F19*H19 -> 450
B20: CELTIK Stone Steps | F20: 10 | G20: Each | H20: 95 | I20: =F20*H20 -> 950
B21: River Stone (Decorative) | F21: 2 | G21: Tons | H21: 48.67 | I21: =F21*H21 -> 97.34
B22: Wood Landing & Steps Material | F22: 43 | G22: Sq. Ft. | H22: 15 | I22: =F22*H22 -> 645
B23: Black Vinyl Chainlink Fence | F23: 200 | G23: Lin. Ft. | H23: 11 | I23: =F23*H23 -> 2200
... B56: Chanticleer Flowering Pear 50mm | F56: 1 | G56: Each | H56: 190 | I56: =F56*H56 -> 190
B57: Mulch (50lbs bag) | F57: 200 | G57: Bags | H57: 10 | I57: 5510
B58: Labor
B59: Flagstone Stepping Stones (Excavate & Set) | F59: 7.5 | G59: Hrs L | H59: 23 | J59: =F59*H59 -> 172.5
B60: Tumbled Pavers (Screed, Lay, Cut, Compact) | F60: 94.6 | G60: Hrs L | H60: 23 | J60: =F60*H60 -> 2175.8
B61: Paver Border (Soldier Course - Cutting/Setting) | F61: 38.5 | G61: Hrs L | H61: 23 | J61: =F61*H61 -> 885.5
B62: Flagstone Porch (Mortar Overlay Installation) | F62: 20.4 | G62: Hrs L | H62: 23 | J62: =F62*H62 -> 469.2
B63: Exposed Aggregate Concrete (Form, Pour, Wash)** | F63: 114.8 | G63: Hrs L | H63: 23 | J63: =F63*H63 -> 2640.4
B64: Armour Stone Outcropping (Machine Set***) | F64: 13.5 | G64: Hrs L | H64: 23 | J64: =F64*H64 -> 310.5
B65: Armour Stone Boulders (Placement) | F65: 2.5 | G65: Hrs L | H65: 23 | J65: =F65*H65 -> 57.5
B66: Natural Stone Garden Wall (Stacking) | F66: 22.8 | G66: Hrs L | H66: 23 | J66: =F66*H66 -> 524.4
B67: CELTIK Stone Steps (Base Prep & Set) | F67: 15 | G67: Hrs L | H67: 23 | J67: =F67*H67 -> 345
B68: River Stone (Spreading) | F68: 2 | G68: Hrs L | H68: 23 | J68: =F68*H68 -> 46
B69: Wood Landing & Steps (Carpentry/Assembly) | F69: 21.5 | G69: Hrs L | H69: 23 | J69: =F69*H69 -> 494.5
B70: Black Vinyl Chainlink Fence (Auger & Install) | F70: 40 | G70: Hrs L | H70: 23 | J70: =F70*H70 -> 920
... B75: Mulch installation | F75: 30 | G75: Hrs L | H75: 23 | J75: =F75*H75 -> 690
B76: Equipment
...

Sheet Lawn Installation
B1: Project: | C1: ='1. Setup & Recap'!O10 | F1: Date: | G1: ='1. Setup & Recap'!O9
B2: Location: | C2: ='1. Setup & Recap'!O11 | F2: Estimator: | G2: ='1. Setup & Recap'!O16 -> Hayden Lutz, Rob McKenna, John Dickinson | I2: CAW Loaded | J2: =$G$5*(1+$G$6+$G$7) -> 28.06
B3: P.O.C./G.C.: | C3: ='1. Setup & Recap'!O12 | F3: Crew Size: | G3: ='1. Setup & Recap'!G3 -> 6
B4: Phone / Fax: | C4: ='1. Setup & Recap'!O13 | F4: Hours/Day: | G4: ='1. Setup & Recap'!G5 -> 10
B5: Due Date: | C5: ='1. Setup & Recap'!O14 | F5: CAW: | G5: =CAW -> 23 | I5: Phase 1 | J5: Quantity | K5: Unit
B6: Type Work: | F6: Risk Factor | G6: ='1. Setup & Recap'!G7 -> 0.12 | I6: Total Labor Hrs | J6: =DSUM(F9:G997,F9,K5:K6) -> 16.9 | K6: Hrs L
F7: OT Factor | G7: ='1. Setup & Recap'!G6 -> 0.1
F8: Column Calcualtions | I8: =F8*H8 -> #VALUE! | J8: =F8*H8 -> #VALUE! | K8: =F8*H8 -> #VALUE! | L8: =F8*H8 -> #VALUE!
A9: # | B9: Description | F9: Quantity | G9: Unit | H9: Unit Cost | I9: Material | J9: Labor | K9: Equip | L9: Subs
B10: TOTALS | I10: =SUM(I11:I997) -> 1710 | J10: =SUM(J11:J997) -> 388.7 | K10: =SUM(K11:K997) -> 24.9 | L10: =SUM(L11:L997) -> 0
B11: Materials | I11: =F11*H11 -> 0
B12: Palisades Zoysia Sod (450 sq. ft. per pallet) | F12: 3 | G12: Pallet | H12: 335 | I12: =F12*H12 -> 1005
B13: Delivery Fee (Flat Rate - Sod Farm) | F13: 1 | G13: LS | H13: 175 | I13: =F13*H13 -> 175
B14: Bulk Garden Mix / Premium Topsoil | F14: 8 | G14: CY | H14: 45 | I14: =F14*H14 -> 360
B15: Delivery Fee (Bulk Soil Dump Truck) | F15: 1 | G15: LS | H15: 125 | I15: =F15*H15 -> 125
B16: Starter Fertilizer (High Phosphorus) | F16: 1 | G16: Bag | H16: 45 | I16: =F16*H16 -> 45
B19: Labor | J19: =F19*H19 -> 0
B20: Spread Topsoil (Wheelbarrow) | F20: 1.2 | G20: Hrs L | H20: 23 | J20: =F20*H20 -> 27.6
B21: Fine Grading (Hand Rake) | F21: 13.5 | G21: Hrs L | H21: 23 | J21: =F21*H21 -> 310.5
B22: Lay Sod (St. Aug/Zoysia) | F22: 1.2 | G22: Hrs L | H22: 23 | J22: =F22*H22 -> 27.6
B23: Fertilizer Application (Rotary) | F23: 1 | G23: Hrs L | H23: 23 | J23: =F23*H23 -> 23
B25: Equipment
B26: Handtools | F26: 24.9 | G26: HR | H26: 1 | K26: =F26*H26 -> 24.9

Sheet 2-C. Production costs
B1: Project: | C1: ='1. Setup & Recap'!O10 | F1: Date: | G1: ='1. Setup & Recap'!O9
B2: Location: | C2: ='1. Setup & Recap'!O11 | F2: Estimator: | G2: ='1. Setup & Recap'!O16 -> Hayden Lutz, Rob McKenna, John Dickinson | I2: CAW Loaded | J2: =$G$5*(1+$G$6+$G$7) -> 28.06
B3: P.O.C./G.C.: | C3: ='1. Setup & Recap'!O12 | F3: Crew Size: | G3: ='1. Setup & Recap'!G3 -> 6
B4: Phone / Fax: | C4: ='1. Setup & Recap'!O13 | F4: Hours/Day: | G4: ='1. Setup & Recap'!G5 -> 10
B5: Due Date: | C5: ='1. Setup & Recap'!O14 | F5: CAW: | G5: =CAW -> 23 | I5: Phase 1 | J5: Quantity | K5: Unit
B6: Type Work: | F6: Risk Factor | G6: ='1. Setup & Recap'!G7 -> 0.12 | I6: Total Labor Hrs | J6: =DSUM(F9:G997,F9,K5:K6) -> 0 | K6: Hrs L
F7: OT Factor | G7: ='1. Setup & Recap'!G6 -> 0.1
F8: Column Calcualtions | I8: =F8*H8 -> #VALUE! | J8: =F8*H8 -> #VALUE! | K8: =F8*H8 -> #VALUE! | L8: =F8*H8 -> #VALUE!
A9: # | B9: Description | F9: Quantity | G9: Unit | H9: Unit Cost | I9: Material | J9: Labor | K9: Equip | L9: Subs
B10: TOTALS | I10: =SUM(I11:I997) -> 0 | J10: =SUM(J11:J997) -> 0 | K10: =SUM(K11:K997) -> 0 | L10: =SUM(L11:L997) -> 0
B11: Materials | F11: 0 | G11: EA | H11: 1 | I11: =F11*H11 -> 0
F12: 0 | G12: EA | H12: 1 | I12: =F12*H12 -> 0
F13: 0 | G13: EA | H13: 1 | I13: =F13*H13 -> 0
F14: 0 | G14: EA | H14: 1 | I14: =F14*H14 -> 0
F15: 0 | G15: EA | H15: 1 | I15: =F15*H15 -> 0
F16: 0 | G16: EA | H16: 1 | I16: =F16*H16 -> 0
I17: =F17*H17 -> 0
B19: Labor | F19: 0 | G19: Hrs L | H19: =$J$2 -> 28.06 | J19: =F19*H19 -> 0
F20: 0 | G20: Hrs L | H20: =$J$2 -> 28.06 | J20: =F20*H20 -> 0
F21: 0 | J21: =F21*H21 -> 0
B33: Equipment | F33: 0 | G33: HR | H33: 1 | K33: =F33*H33 -> 0
F34: 0 | G34: HR | H34: 1 | K34: =F34*H34 -> 0

Sheet 3. GC costs
B1: Project: | C1: ='Landscape Intallation'!C1 | F1: Date: | G1: ='Landscape Intallation'!G1
B2: Location: | C2: ='Landscape Intallation'!C2 | F2: Estimator: | G2: ='Landscape Intallation'!G2 -> Hayden Lutz, Rob McKenna, John Dickinson | I2: CAW Loaded | J2: =$G$5*(1+$G$6+$G$7) -> 28.06
B3: P.O.C./G.C.: | C3: ='Landscape Intallation'!C3 | F3: Crew Size: | G3: ='Landscape Intallation'!G3 -> 6
B4: Phone / Fax: | C4: ='Landscape Intallation'!C4 | F4: Hours/Day: | G4: ='Landscape Intallation'!G4 -> 10
B5: Due Date: | C5: ='Landscape Intallation'!C5 | F5: CAW: | G5: ='Landscape Intallation'!G5 -> 23 | I5: Phase 2 | J5: Quantity | K5: Unit
B6: Type Work: | C6: General conditions | F6: Risk Factor | G6: ='Landscape Intallation'!G6 -> 0.12 | I6: Total Labor Hrs | J6: =DSUM(F9:G1000,F9,K5:K6) -> 127 | K6: Hrs L
F7: OT Factor | G7: ='Landscape Intallation'!G7 -> 0.1
F8: Column Calcualtions | I8: =F8*H8 -> #VALUE! | J8: =F8*H8 -> #VALUE! | K8: =F8*H8 -> #VALUE! | L8: =F8*H8 -> #VALUE!
A9: # | B9: Description | F9: Quantity | G9: Unit | H9: Unit Cost | I9: Material | J9: Labor | K9: Equip | L9: Subs
B10: TOTALS | E10: hr/day | I10: =SUM(I11:I1000) -> 40 | J10: =SUM(J11:J1000) -> 3225 | K10: =SUM(K11:K1000) -> 1140 | L10: =SUM(L11:L1000) -> 0
B11: Superintendent (1 hour per day) | E11: 1 | F11: =E11*'1. Setup & Recap'!$G$15 -> 9 | G11: Hrs L | H11: 45 | J11: =F11*H11 -> 405
B12: Superintendent Truck | E12: 1 | F12: =E12*'1. Setup & Recap'!$G$15 -> 9 | G12: Hrs | H12: 45 | K12: =F12*H12 -> 405
B13: Foreman admin time (1 Hr / Day) | E13: 1 | F13: =E13*'1. Setup & Recap'!$G$15 -> 9 | G13: Hrs L | H13: 35 | J13: =F13*H13 -> 315
B14: Crew Truck (8 hrs/day) | E14: 8 | F14: =E14*'1. Setup & Recap'!$G$15 -> 72 | G14: Hrs | H14: 10 | K14: =F14*H14 -> 720
B15: Drive Time (1 hr/day / man) | E15: 1 | F15: ='1. Setup & Recap'!G3*E15*'1. Setup & Recap'!$G$15 -> 54 | G15: Hrs L | H15: 23 | J15: =F15*H15 -> 1242
B16: Load / Unload Time (1 hr/day/man) | E16: 1 | F16: ='1. Setup & Recap'!G3*E16*'1. Setup & Recap'!$G$15 -> 54 | G16: Hrs L | H16: 23 | J16: =F16*H16 -> 1242
B17: Dump Fees ($40 per trip) | E17: N/A | F17: 1 | G17: LS | H17: 40 | I17: =F17*H17 -> 40
B18: Warranty Labor | E18: N/A | F18: 1 | G18: Hrs L | H18: 21 | J18: =F18*H18 -> 21
B19: Warranty Equipment | E19: N/A | F19: 1 | G19: Hrs | H19: 15 | K19: =F19*H19 -> 15
